Workbook
Name UPDATE: 'Data Sheet'!$E$1

Sheet Data Sheet
A1: COMPANY NAME | B1: TATA STEEL LTD | E1: =IF(B2<>B3, "A NEW VERSION OF THE WORKSHEET IS AVAILABLE", "")
A2: LATEST VERSION | B2: 2.1 | E2: PLEASE DO NOT MAKE ANY CHANGES TO THIS SHEET
A3: CURRENT VERSION | B3: 2.1
A5: META
A6: Number of shares | B6: =IF(B9>0, B9/B8, 0) -> 1248.3526
A7: Face Value | B7: 1
A8: Current Price | B8: 188.4
A9: Market Capitalization | B9: 235189.63
A15: PROFIT & LOSS
A16: Report Date | B16: 42825 | C16: 43190 | D16: 43555 | E16: 43921 | F16: 44286 | G16: 44651 | H16: 45016 | I16: 45382 | J16: 45747 | K16: 46112
A17: Sales | B17: 112299.42 | C17: 123249.07 | D17: 157668.99 | E17: 139816.65 | F17: 156477.4 | G17: 243959.17 | H17: 243352.69 | I17: 229170.78 | J17: 218542.51 | K17: 232139.94
A18: Raw Material Cost | B18: 43843.03 | C18: 46137.01 | D18: 60877.05 | E18: 58039.99 | F18: 55100.81 | G18: 91076.61 | H18: 116597.19 | I18: 97506.39 | J18: 95097.3 | K18: 92628.07
A19: Change in Inventory | B19: 4538.13 | C19: -99.31 | D19: 96.71 | E19: 565.24 | F19: -1516.77 | G19: 7597.87 | H19: 3358.89 | I19: -4409.35 | J19: 96.65 | K19: -989.62
A20: Power and Fuel | B20: 5220.83 | C20: 4440.43 | D20: 5316.56 | E20: 5319.92 | F20: 5708.42 | G20: 8028.29 | H20: 9526.91 | I20: 16612.61 | J20: 13124.85 | K20: 14333.15
A21: Other Mfr. Exp | B21: 15799.14 | C21: 16955.79 | D21: 20734.28 | E21: 21232.69 | F21: 20744.93 | G21: 28834.06 | H21: 33144.83 | I21: 40116.91 | J21: 38700.5 | K21: 37485.96
A22: Employee Cost | B22: 17252.22 | C22: 17077.51 | D22: 18758.87 | E22: 18533.58 | F22: 19908.81 | G22: 23264.1 | H22: 22419.32 | I22: 24509.58 | J22: 24888.99 | K22: 25998.98
A23: Selling and admin | B23: 13772.32 | C23: 14423.87 | D23: 16917.14 | E23: 15599.07 | F23: 17509.77 | G23: 27445.67 | H23: 25519.92 | I23: 14453.57 | J23: 12137.26 | K23: 13348.99
A24: Other Expenses | B24: 7806.38 | C24: 2681.96 | D24: 5843.58 | E24: 4193.58 | F24: 5483.63 | G24: 9418.36 | H24: 7203.25 | I24: 9314.45 | J24: 9391.81 | K24: 13002.73
A25: Other Income | B25: -3789.11 | C25: 10898.41 | D25: 1524.31 | E25: -2883.63 | F25: 179.78 | G25: 1299.99 | H25: 1568.86 | I25: -6005.23 | J25: 876.7 | K25: 737.82
A26: Depreciation | B26: 5672.88 | C26: 5741.7 | D26: 7341.83 | E26: 8440.73 | F26: 9233.64 | G26: 9100.87 | H26: 9335.2 | I26: 9882.16 | J26: 10421.33 | K26: 11954.51
A27: Interest | B27: 5072.2 | C27: 5454.74 | D27: 7660.1 | E27: 7533.46 | F27: 7606.71 | G27: 5462.2 | H27: 6298.7 | I27: 7507.57 | J27: 7340.95 | K27: 7167.06
... A31: Dividend Amount | B31: 970.24 | C31: 1144.95 | D31: 1488.42 | E31: 1144.95 | F31: 2994.02 | G31: 6228.17 | H31: 4396.46 | I31: 4490.78 | J31: 4490.78 | K31: 4989.76
C33: =C30-C25 -> 2535.92
B35: =379 -> 379
A37: EBITDA | B37: =B30+B29+B27+B26 -> 9282.29 | C37: =C30+C29+C27+C26 -> 28023.1 | D37: =D30+D29+D27+D26 -> 31938.69 | E37: =E30+E29+E27+E26 -> 14962.32 | F37: =F30+F29+F27+F26 -> 29984.47 | G37: =G30+G29+G27+G26 -> 63194.55 | H37: =H30+H29+H27+H26 -> 34554.07 | I37: =I30+I29+I27+I26 -> 16714.86 | ... K37: =K30+K29+K27+K26 -> 34998.31
A40: Quarters
A41: Report Date | B41: 45382 | C41: 45473 | D41: 45565 | E41: 45657 | F41: 45747 | G41: 45838 | H41: 45930 | I41: 46022 | J41: 46112 | K41: 46203
A42: Sales | B42: 58687.31 | C42: 54771.39 | D42: 53904.71 | E42: 53648.3 | F42: 56218.11 | G42: 53178.12 | H42: 58689.29 | I42: 57002.4 | J42: 63270.13 | K42: 60794.29
A43: Expenses | B43: 52086.68 | C43: 48076.92 | D43: 47788.92 | E43: 47744.81 | F43: 49658.89 | G43: 45750.58 | H43: 49792.75 | I43: 48802.7 | J43: 53441.47 | K43: 51529.95
A44: Other Income | B44: -381.56 | C44: -5.51 | D44: 616.68 | E44: 141.82 | F44: 149.19 | G44: 236.27 | H44: -6.11 | I44: 465.17 | J44: 42.49 | K44: -16.65
A45: Depreciation | B45: 2567.95 | C45: 2535.43 | D45: 2596.74 | E45: 2569.19 | F45: 2719.97 | G45: 2744.3 | H45: 2893 | I45: 3048.81 | J45: 3268.4 | K45: 3639.65
A46: Interest | B46: 1842.25 | C46: 1776.71 | D46: 1971.4 | E46: 1804.09 | F46: 1788.75 | G46: 1852.43 | H46: 1774.96 | I46: 1747.29 | J46: 1792.38 | K46: 1770.51
A47: Profit before tax | B47: 1808.87 | C47: 2376.82 | D47: 2164.33 | E47: 1672.03 | F47: 2199.69 | G47: 3067.08 | H47: 4222.47 | I47: 3868.77 | J47: 4810.37 | K47: 3837.53
A48: Tax | B48: 1254.31 | C48: 1458.25 | D48: 1405.49 | E48: 1376.54 | F48: 998.81 | G48: 1059.72 | H48: 1039.38 | I48: 1138.4 | J48: 1845.37 | K48: 1452.29
A49: Net profit | B49: 611.48 | C49: 959.61 | D49: 833.45 | E49: 326.64 | F49: 1300.81 | G49: 2077.68 | H49: 3101.75 | I49: 2688.7 | J49: 2925.74 | K49: 2318.35
A50: Operating Profit | B50: 6600.63 | C50: 6694.47 | D50: 6115.79 | E50: 5903.49 | F50: 6559.22 | G50: 7427.54 | H50: 8896.54 | I50: 8199.7 | J50: 9828.66 | K50: 9264.34
A55: BALANCE SHEET
A56: Report Date | B56: 42825 | C56: 43190 | D56: 43555 | E56: 43921 | F56: 44286 | G56: 44651 | H56: 45016 | I56: 45382 | J56: 45747 | K56: 46112
A57: Equity Share Capital | B57: 970.24 | C57: 1144.95 | D57: 1144.94 | E57: 1144.95 | F57: 1197.61 | G57: 1221.21 | H57: 1221.24 | I57: 1247.44 | J57: 1247.44 | K57: 1247.44
A58: Reserves | B58: 36849.08 | C58: 59725.67 | D58: 67780.14 | E58: 72431.35 | F58: 73041.16 | G58: 113221.83 | H58: 101860.86 | I58: 90788.32 | J58: 89922.19 | K58: 100920.21
...

Sheet HistoricalFS 
B2: ="Historical Financial Statement- "&'Data Sheet'!B1 -> Historical Financial Statement- TATA STEEL LTD
B3: Years | C3: ='Data Sheet'!B16 -> 42825 | D3: ='Data Sheet'!C16 -> 43190 | E3: ='Data Sheet'!D16 -> 43555 | F3: ='Data Sheet'!E16 -> 43921 | G3: ='Data Sheet'!F16 -> 44286 | H3: ='Data Sheet'!G16 -> 44651 | I3: ='Data Sheet'!H16 -> 45016 | J3: ='Data Sheet'!I16 -> 45382 | ... L3: ='Data Sheet'!K16 -> 46112 | M3: LTM
A4: # | B4: Income Statement
B5: Sales | C5: =IFERROR('Data Sheet'!B17,0) -> 112299.42 | D5: =IFERROR('Data Sheet'!C17,0) -> 123249.07 | E5: =IFERROR('Data Sheet'!D17,0) -> 157668.99 | F5: =IFERROR('Data Sheet'!E17,0) -> 139816.65 | G5: =IFERROR('Data Sheet'!F17,0) -> 156477.4 | H5: =IFERROR('Data Sheet'!G17,0) -> 243959.17 | I5: =IFERROR('Data Sheet'!H17,0) -> 243352.69 | J5: =IFERROR('Data Sheet'!I17,0) -> 229170.78 | ... L5: =IFERROR('Data Sheet'!K17,0) -> 232139.94 | M5: =IFERROR(SUM('Data Sheet'!H42:K42),0) -> 239756.11
B6: Sale Growth | C6: - | D6: =D5/C5-1 -> 0.097504065 | E6: =E5/D5-1 -> 0.27927124 | F6: =F5/E5-1 -> -0.1132267 | G6: =G5/F5-1 -> 0.11916142 | H6: =H5/G5-1 -> 0.55906968 | I6: =I5/H5-1 -> -0.0024859898 | J6: =J5/I5-1 -> -0.058277186 | K6: =K5/J5-1 -> -0.046377073 | ... M6: =M5/L5-1 -> 0.032808529
B8: COGS | C8: =IFERROR(SUM('Data Sheet'!B18,'Data Sheet'!B20:B22) -1*'Data Sheet'!B19,0) -> 77577.09 | D8: =IFERROR(SUM('Data Sheet'!C18,'Data Sheet'!C20:C22) -1*'Data Sheet'!C19,0) -> 84710.05 | E8: =IFERROR(SUM('Data Sheet'!D18,'Data Sheet'!D20:D22) -1*'Data Sheet'!D19,0) -> 105590.05 | F8: =IFERROR(SUM('Data Sheet'!E18,'Data Sheet'!E20:E22) -1*'Data Sheet'!E19,0) -> 102560.94 | G8: =IFERROR(SUM('Data Sheet'!F18,'Data Sheet'!F20:F22) -1*'Data Sheet'!F19,0) -> 102979.74 | H8: =IFERROR(SUM('Data Sheet'!G18,'Data Sheet'!G20:G22) -1*'Data Sheet'!G19,0) -> 143605.19 | I8: =IFERROR(SUM('Data Sheet'!H18,'Data Sheet'!H20:H22) -1*'Data Sheet'!H19,0) -> 178329.36 | J8: =IFERROR(SUM('Data Sheet'!I18,'Data Sheet'!I20:I22) -1*'Data Sheet'!I19,0) -> 183154.84 | ... L8: =IFERROR(SUM('Data Sheet'!K18,'Data Sheet'!K20:K22) -1*'Data Sheet'!K19,0) -> 171435.78 | M8: =IFERROR(SUM('Data Sheet'!H43:K43),0) -> 203566.87
B9: COGS % Sales | C9: =C8/C5 -> 0.69080579 | D9: =D8/D5 -> 0.68730782 | E9: =E8/E5 -> 0.66969447 | F9: =F8/F5 -> 0.73353882 | G9: =G8/G5 -> 0.65811255 | H9: =H8/H5 -> 0.58864436 | I9: =I8/I5 -> 0.73280209 | J9: =J8/J5 -> 0.79920677 | ... M9: =M8/M5 -> 0.84905811
B11: Gross Profit | C11: =IFERROR(C5-C8,0) -> 34722.33 | D11: =IFERROR(D5-D8,0) -> 38539.02 | E11: =IFERROR(E5-E8,0) -> 52078.94 | F11: =IFERROR(F5-F8,0) -> 37255.71 | G11: =IFERROR(G5-G8,0) -> 53497.66 | H11: =IFERROR(H5-H8,0) -> 100353.98 | I11: =IFERROR(I5-I8,0) -> 65023.33 | J11: =IFERROR(J5-J8,0) -> 46015.94 | ... M11: =IFERROR(M5-M8,0) -> 36189.24
B12: Gross Margin | C12: =IFERROR(C11/C5,0) -> 0.30919421 | D12: =IFERROR(D11/D5,0) -> 0.31269218 | E12: =IFERROR(E11/E5,0) -> 0.33030553 | F12: =IFERROR(F11/F5,0) -> 0.26646118 | G12: =IFERROR(G11/G5,0) -> 0.34188745 | H12: =IFERROR(H11/H5,0) -> 0.41135564 | I12: =IFERROR(I11/I5,0) -> 0.26719791 | J12: =IFERROR(J11/J5,0) -> 0.20079323 | ... M12: =IFERROR(M11/M5,0) -> 0.15094189
B14: Selling and General Expenses | C14: =IFERROR(SUM('Data Sheet'!B23:B24),0) -> 21578.7 | D14: =IFERROR(SUM('Data Sheet'!C23:C24),0) -> 17105.83 | E14: =IFERROR(SUM('Data Sheet'!D23:D24),0) -> 22760.72 | F14: =IFERROR(SUM('Data Sheet'!E23:E24),0) -> 19792.65 | G14: =IFERROR(SUM('Data Sheet'!F23:F24),0) -> 22993.4 | H14: =IFERROR(SUM('Data Sheet'!G23:G24),0) -> 36864.03 | I14: =IFERROR(SUM('Data Sheet'!H23:H24),0) -> 32723.17 | J14: =IFERROR(SUM('Data Sheet'!I23:I24),0) -> 23768.02 | ... M14: =IFERROR(SUM('Data Sheet'!L23:L24),0) -> 0
B15: S&G Exp % Sales | C15: =C14/C5 -> 0.19215326 | D15: =D14/D5 -> 0.13879074 | E15: =E14/E5 -> 0.14435762 | F15: =F14/F5 -> 0.14156147 | G15: =G14/G5 -> 0.1469439 | H15: =H14/H5 -> 0.15110738 | I15: =I14/I5 -> 0.13446808 | J15: =J14/J5 -> 0.10371313 | ... M15: =M14/M5 -> 0
B17: EBITDA | C17: =IFERROR(C11-C14,0) -> 13143.63 | D17: =IFERROR(D11-D14,0) -> 21433.19 | E17: =IFERROR(E11-E14,0) -> 29318.22 | F17: =IFERROR(F11-F14,0) -> 17463.06 | G17: =IFERROR(G11-G14,0) -> 30504.26 | H17: =IFERROR(H11-H14,0) -> 63489.95 | I17: =IFERROR(I11-I14,0) -> 32300.16 | J17: =IFERROR(J11-J14,0) -> 22247.92 | ... M17: =IFERROR(M11-M14,0) -> 36189.24
B18: EBITDA Margin | C18: =C17/C5 -> 0.11704094 | D18: =D17/D5 -> 0.17390143 | E18: =E17/E5 -> 0.18594792 | F18: =F17/F5 -> 0.12489972 | G18: =G17/G5 -> 0.19494355 | H18: =H17/H5 -> 0.26024826 | I18: =I17/I5 -> 0.13272983 | J18: =J17/J5 -> 0.09708009 | ... M18: =M17/M5 -> 0.15094189
B20: Interest | C20: =IFERROR('Data Sheet'!B27,0) -> 5072.2 | D20: =IFERROR('Data Sheet'!C27,0) -> 5454.74 | E20: =IFERROR('Data Sheet'!D27,0) -> 7660.1 | F20: =IFERROR('Data Sheet'!E27,0) -> 7533.46 | G20: =IFERROR('Data Sheet'!F27,0) -> 7606.71 | H20: =IFERROR('Data Sheet'!G27,0) -> 5462.2 | I20: =IFERROR('Data Sheet'!H27,0) -> 6298.7 | J20: =IFERROR('Data Sheet'!I27,0) -> 7507.57 | ... L20: =IFERROR('Data Sheet'!K27,0) -> 7167.06 | M20: =IFERROR(SUM('Data Sheet'!H46:K46),0) -> 7085.14
B21: Interest % Sales | C21: =C20/C5 -> 0.045166752 | D21: =D20/D5 -> 0.044257859 | E21: =E20/E5 -> 0.048583428 | F21: =F20/F5 -> 0.053880993 | G21: =G20/G5 -> 0.048612196 | H21: =H20/H5 -> 0.022389812 | I21: =I20/I5 -> 0.02588301 | J21: =J20/J5 -> 0.032759717 | ... M21: =M20/M5 -> 0.029551447
B23: Deprication | C23: =IFERROR('Data Sheet'!B26,0) -> 5672.88 | D23: =IFERROR('Data Sheet'!C26,0) -> 5741.7 | E23: =IFERROR('Data Sheet'!D26,0) -> 7341.83 | F23: =IFERROR('Data Sheet'!E26,0) -> 8440.73 | G23: =IFERROR('Data Sheet'!F26,0) -> 9233.64 | H23: =IFERROR('Data Sheet'!G26,0) -> 9100.87 | I23: =IFERROR('Data Sheet'!H26,0) -> 9335.2 | J23: =IFERROR('Data Sheet'!I26,0) -> 9882.16 | ... L23: =IFERROR('Data Sheet'!K26,0) -> 11954.51 | M23: =IFERROR(SUM('Data Sheet'!H45:K45),0) -> 12849.86
B24: Deprication % Sales | C24: =C23/C5 -> 0.050515666 | D24: =D23/D5 -> 0.046586153 | E24: =E23/E5 -> 0.046564832 | F24: =F23/F5 -> 0.060369992 | G24: =G23/G5 -> 0.059009416 | H24: =H23/H5 -> 0.03730489 | I24: =I23/I5 -> 0.038360784 | J24: =J23/J5 -> 0.043121379 | ... M24: =M23/M5 -> 0.053595548
B26: EBT/ Profit | C26: =IFERROR(C17-SUM(C20,C23),0) -> 2398.55 | D26: =IFERROR(D17-SUM(D20,D23),0) -> 10236.75 | E26: =IFERROR(E17-SUM(E20,E23),0) -> 14316.29 | F26: =IFERROR(F17-SUM(F20,F23),0) -> 1488.87 | G26: =IFERROR(G17-SUM(G20,G23),0) -> 13663.91 | H26: =IFERROR(H17-SUM(H20,H23),0) -> 48926.88 | I26: =IFERROR(I17-SUM(I20,I23),0) -> 16666.26 | J26: =IFERROR(J17-SUM(J20,J23),0) -> 4858.19 | ... M26: =IFERROR(M17-SUM(M20,M23),0) -> 16254.24
B27: EBT % Sales | C27: =C26/C5 -> 0.021358525 | D27: =D26/D5 -> 0.083057422 | E27: =E26/E5 -> 0.090799656 | F27: =F26/F5 -> 0.010648732 | G27: =G26/G5 -> 0.087321939 | H27: =H26/H5 -> 0.20055356 | I27: =I26/I5 -> 0.068486032 | J27: =J26/J5 -> 0.021198994 | ... M27: =M26/M5 -> 0.067794894
B29: Tax | C29: =IFERROR('Data Sheet'!B29,0) -> 2778.01 | D29: =IFERROR('Data Sheet'!C29,0) -> 3392.33 | E29: =IFERROR('Data Sheet'!D29,0) -> 6718.43 | F29: =IFERROR('Data Sheet'!E29,0) -> -2568.41 | G29: =IFERROR('Data Sheet'!F29,0) -> 5653.9 | H29: =IFERROR('Data Sheet'!G29,0) -> 8477.55 | I29: =IFERROR('Data Sheet'!H29,0) -> 10159.77 | J29: =IFERROR('Data Sheet'!I29,0) -> 3762.57 | ... L29: =IFERROR('Data Sheet'!K29,0) -> 5082.87 | M29: =IFERROR(SUM('Data Sheet'!H48:K48),0) -> 5475.44
B30: Effective Tax Rate | C30: =C29/C26 -> 1.1582039 | D30: =D29/D26 -> 0.3313874 | E30: =E29/E26 -> 0.46928569 | F30: =F29/F26 -> -1.7250734 | G30: =G29/G26 -> 0.41378346 | H30: =H29/H26 -> 0.17326979 | I30: =I29/I26 -> 0.60960107 | J30: =J29/J26 -> 0.7744798 | ... M30: =M29/M26 -> 0.33686226
B32: Net Profit | C32: =IFERROR(C26-C29,0) -> -379.46 | D32: =IFERROR(D26-D29,0) -> 6844.42 | E32: =IFERROR(E26-E29,0) -> 7597.86 | F32: =IFERROR(F26-F29,0) -> 4057.28 | G32: =IFERROR(G26-G29,0) -> 8010.01 | H32: =IFERROR(H26-H29,0) -> 40449.33 | I32: =IFERROR(I26-I29,0) -> 6506.49 | J32: =IFERROR(J26-J29,0) -> 1095.62 | ... M32: =IFERROR(M26-M29,0) -> 10778.8
B33: Net margin | C33: =C32/C5 -> -0.0033790023 | D33: =D32/D5 -> 0.055533239 | E33: =E32/E5 -> 0.048188677 | F33: =F32/F5 -> 0.029018575 | G33: =G32/G5 -> 0.051189565 | H33: =H32/H5 -> 0.16580369 | I33: =I32/I5 -> 0.026736873 | J33: =J32/J5 -> 0.0047808015 | ... M33: =M32/M5 -> 0.044957353
B35: No. of Equity Shares | C35: =IFERROR('Data Sheet'!B93,0) -> 1126.62 | D35: =IFERROR('Data Sheet'!C93,0) -> 1126.48 | E35: =IFERROR('Data Sheet'!D93,0) -> 1126.49 | F35: =IFERROR('Data Sheet'!E93,0) -> 1126.49 | G35: =IFERROR('Data Sheet'!F93,0) -> 1196.59 | H35: =IFERROR('Data Sheet'!G93,0) -> 1221.3 | I35: =IFERROR('Data Sheet'!H93,0) -> 1222.15 | J35: =IFERROR('Data Sheet'!I93,0) -> 1248.35 | ... M35: =IFERROR('Data Sheet'!L93,0) -> 0
B37: Earning Per Share | C37: =IFERROR(C32/C35,0) -> -0.33681277 | D37: =IFERROR(D32/D35,0) -> 6.0759357 | E37: =IFERROR(E32/E35,0) -> 6.7447203 | F37: =IFERROR(F32/F35,0) -> 3.6017009 | G37: =IFERROR(G32/G35,0) -> 6.6940305 | H37: =IFERROR(H32/H35,0) -> 33.119897 | I37: =IFERROR(I32/I35,0) -> 5.3238064 | J37: =IFERROR(J32/J35,0) -> 0.8776545 | ... M37: =IFERROR(M32/M35,0) -> 0
B38: Earning Growth % | D38: =IFERROR(D37/-C37-1,0) -> 17.039505 | E38: =IFERROR(E37/D37-1,0) -> 0.11007106 | F38: =IFERROR(F37/E37-1,0) -> -0.465997 | G38: =IFERROR(G37/F37-1,0) -> 0.85857482 | H38: =IFERROR(H37/G37-1,0) -> 3.9476764 | I38: =IFERROR(I37/H37-1,0) -> -0.83925655 | J38: =IFERROR(J37/I37-1,0) -> -0.8351453 | K38: =IFERROR(K37/J37-1,0) -> 1.0966028 | L38: =IFERROR(L37/K37-1,0) -> 3.4177826
B40: Dividend Per Share | C40: =IFERROR('Data Sheet'!B31/'HistoricalFS '!C35,0) -> 0.86119543 | D40: =IFERROR('Data Sheet'!C31/'HistoricalFS '!D35,0) -> 1.0163962 | E40: =IFERROR('Data Sheet'!D31/'HistoricalFS '!E35,0) -> 1.32129 | F40: =IFERROR('Data Sheet'!E31/'HistoricalFS '!F35,0) -> 1.0163872 | G40: =IFERROR('Data Sheet'!F31/'HistoricalFS '!G35,0) -> 2.5021269 | H40: =IFERROR('Data Sheet'!G31/'HistoricalFS '!H35,0) -> 5.0996234 | I40: =IFERROR('Data Sheet'!H31/'HistoricalFS '!I35,0) -> 3.5973162 | J40: =IFERROR('Data Sheet'!I31/'HistoricalFS '!J35,0) -> 3.5973725 | ... N40: =IFERROR('Data Sheet'!M31/'HistoricalFS '!N35,0) -> 0
B41: Dividend Payout Ratio | C41: =IFERROR(C40/-C37,0) -> 2.5568966 | D41: =IFERROR(D40/D37,0) -> 0.16728225 | E41: =IFERROR(E40/E37,0) -> 0.1958999 | F41: =IFERROR(F40/F37,0) -> 0.28219645 | G41: =IFERROR(G40/G37,0) -> 0.3737848 | H41: =IFERROR(H40/H37,0) -> 0.15397461 | I41: =IFERROR(I40/I37,0) -> 0.6757038 | J41: =IFERROR(J40/J37,0) -> 4.0988481 | K41: =IFERROR(K40/K37,0) -> 1.954995 | ... M41: =IFERROR(M40/M37,0) -> 0
B43: Reatined Earning | C43: =IFERROR(IF(C37>C40,1-C41,0),0) -> 0 | D43: =IFERROR(IF(D37>D40,1-D41,0),0) -> 0.83271775 | E43: =IFERROR(IF(E37>E40,1-E41,0),0) -> 0.8041001 | F43: =IFERROR(IF(F37>F40,1-F41,0),0) -> 0.71780355 | G43: =IFERROR(IF(G37>G40,1-G41,0),0) -> 0.6262152 | H43: =IFERROR(IF(H37>H40,1-H41,0),0) -> 0.84602539 | I43: =IFERROR(IF(I37>I40,1-I41,0),0) -> 0.3242962 | J43: =IFERROR(IF(J37>J40,1-J41,0),0) -> 0 | ... M43: =IFERROR(IF(M37>M40,1-M41,0),0) -> 0
A47: # | B47: Balance Sheet
B48: Equity Share Capital | C48: =IFERROR('Data Sheet'!B57,0) -> 970.24 | D48: =IFERROR('Data Sheet'!C57,0) -> 1144.95 | E48: =IFERROR('Data Sheet'!D57,0) -> 1144.94 | F48: =IFERROR('Data Sheet'!E57,0) -> 1144.95 | G48: =IFERROR('Data Sheet'!F57,0) -> 1197.61 | H48: =IFERROR('Data Sheet'!G57,0) -> 1221.21 | I48: =IFERROR('Data Sheet'!H57,0) -> 1221.24 | J48: =IFERROR('Data Sheet'!I57,0) -> 1247.44 | ... L48: =IFERROR('Data Sheet'!K57,0) -> 1247.44
B49: Reserves | C49: =IFERROR('Data Sheet'!B58,0) -> 36849.08 | D49: =IFERROR('Data Sheet'!C58,0) -> 59725.67 | E49: =IFERROR('Data Sheet'!D58,0) -> 67780.14 | F49: =IFERROR('Data Sheet'!E58,0) -> 72431.35 | G49: =IFERROR('Data Sheet'!F58,0) -> 73041.16 | H49: =IFERROR('Data Sheet'!G58,0) -> 113221.83 | I49: =IFERROR('Data Sheet'!H58,0) -> 101860.86 | J49: =IFERROR('Data Sheet'!I58,0) -> 90788.32 | ... L49: =IFERROR('Data Sheet'!K58,0) -> 100920.21
B50: Borrowings | C50: =IFERROR('Data Sheet'!B59,0) -> 83014.49 | D50: =IFERROR('Data Sheet'!C59,0) -> 92147.05 | E50: =IFERROR('Data Sheet'!D59,0) -> 100816.22 | F50: =IFERROR('Data Sheet'!E59,0) -> 116328.2 | G50: =IFERROR('Data Sheet'!F59,0) -> 88501.41 | H50: =IFERROR('Data Sheet'!G59,0) -> 75561.35 | I50: =IFERROR('Data Sheet'!H59,0) -> 84893.05 | J50: =IFERROR('Data Sheet'!I59,0) -> 87082.12 | ... L50: =IFERROR('Data Sheet'!K59,0) -> 92381.68
B51: Other Liabilities | C51: =IFERROR('Data Sheet'!B60,0) -> 51613.56 | D51: =IFERROR('Data Sheet'!C60,0) -> 55704.47 | E51: =IFERROR('Data Sheet'!D60,0) -> 63032.14 | F51: =IFERROR('Data Sheet'!E60,0) -> 59244.62 | G51: =IFERROR('Data Sheet'!F60,0) -> 81169.01 | H51: =IFERROR('Data Sheet'!G60,0) -> 92417.28 | I51: =IFERROR('Data Sheet'!H60,0) -> 97420.63 | J51: =IFERROR('Data Sheet'!I60,0) -> 90194.54 | ... L51: =IFERROR('Data Sheet'!K60,0) -> 101965.29
B52: Total Liabilities | C52: =IFERROR('Data Sheet'!B61,0) -> 172447.37 | D52: =IFERROR('Data Sheet'!C61,0) -> 208722.14 | E52: =IFERROR('Data Sheet'!D61,0) -> 232773.44 | F52: =IFERROR('Data Sheet'!E61,0) -> 249149.12 | G52: =IFERROR('Data Sheet'!F61,0) -> 243909.19 | H52: =IFERROR('Data Sheet'!G61,0) -> 282421.67 | I52: =IFERROR('Data Sheet'!H61,0) -> 285395.78 | J52: =IFERROR('Data Sheet'!I61,0) -> 269312.42 | ... L52: =IFERROR('Data Sheet'!K61,0) -> 296514.62
B54: Net Block | C54: =IFERROR('Data Sheet'!B62,0) -> 92006.55 | D54: =IFERROR('Data Sheet'!C62,0) -> 96104.89 | E54: =IFERROR('Data Sheet'!D62,0) -> 124441.91 | F54: =IFERROR('Data Sheet'!E62,0) -> 134550.66 | G54: =IFERROR('Data Sheet'!F62,0) -> 135775.18 | H54: =IFERROR('Data Sheet'!G62,0) -> 133287.83 | I54: =IFERROR('Data Sheet'!H62,0) -> 146621.46 | J54: =IFERROR('Data Sheet'!I62,0) -> 148814.38 | ... L54: =IFERROR('Data Sheet'!K62,0) -> 179908.13
B55: Capital Work in Progress | C55: =IFERROR('Data Sheet'!B63,0) -> 15784.13 | D55: =IFERROR('Data Sheet'!C63,0) -> 16614.41 | E55: =IFERROR('Data Sheet'!D63,0) -> 18641.21 | F55: =IFERROR('Data Sheet'!E63,0) -> 19496.83 | G55: =IFERROR('Data Sheet'!F63,0) -> 19007.4 | H55: =IFERROR('Data Sheet'!G63,0) -> 22045.55 | I55: =IFERROR('Data Sheet'!H63,0) -> 31213.02 | J55: =IFERROR('Data Sheet'!I63,0) -> 34355.53 | ... L55: =IFERROR('Data Sheet'!K63,0) -> 28496.71
B56: Investments | C56: =IFERROR('Data Sheet'!B64,0) -> 12457.12 | D56: =IFERROR('Data Sheet'!C64,0) -> 17899.47 | E56: =IFERROR('Data Sheet'!D64,0) -> 5738.17 | F56: =IFERROR('Data Sheet'!E64,0) -> 6285.18 | G56: =IFERROR('Data Sheet'!F64,0) -> 10681.93 | H56: =IFERROR('Data Sheet'!G64,0) -> 13139.85 | I56: =IFERROR('Data Sheet'!H64,0) -> 8410.31 | J56: =IFERROR('Data Sheet'!I64,0) -> 6257.57 | ... L56: =IFERROR('Data Sheet'!K64,0) -> 7088.85
B57: Other Assets | C57: =IFERROR(SUM('Data Sheet'!B65)-SUM('Data Sheet'!B67:B69),0) -> 10887.88 | D57: =IFERROR(SUM('Data Sheet'!C65)-SUM('Data Sheet'!C67:C69),0) -> 29418.96 | E57: =IFERROR(SUM('Data Sheet'!D65)-SUM('Data Sheet'!D67:D69),0) -> 37143.68 | F57: =IFERROR(SUM('Data Sheet'!E65)-SUM('Data Sheet'!E67:E69),0) -> 41808.1 | G57: =IFERROR(SUM('Data Sheet'!F65)-SUM('Data Sheet'!F67:F69),0) -> 29846.28 | H57: =IFERROR(SUM('Data Sheet'!G65)-SUM('Data Sheet'!G67:G69),0) -> 36978.69 | I57: =IFERROR(SUM('Data Sheet'!H65)-SUM('Data Sheet'!H67:H69),0) -> 23121.16 | J57: =IFERROR(SUM('Data Sheet'!I65)-SUM('Data Sheet'!I67:I69),0) -> 15786.18 | ... L57: =IFERROR(SUM('Data Sheet'!K65)-SUM('Data Sheet'!K67:K69),0) -> 18797.29
B58: Total Non-Current Assets | C58: =IFERROR(SUM(C54:C57),0) -> 131135.68 | D58: =IFERROR(SUM(D54:D57),0) -> 160037.73 | E58: =IFERROR(SUM(E54:E57),0) -> 185964.97 | F58: =IFERROR(SUM(F54:F57),0) -> 202140.77 | G58: =IFERROR(SUM(G54:G57),0) -> 195310.79 | H58: =IFERROR(SUM(H54:H57),0) -> 205451.92 | I58: =IFERROR(SUM(I54:I57),0) -> 209365.95 | J58: =IFERROR(SUM(J54:J57),0) -> 205213.66 | ... L58: =IFERROR(SUM(L54:L57),0) -> 234290.98
...

Sheet Ratio Analysis
B2: ="Ratio Analysis of - "&'Data Sheet'!B1 -> Ratio Analysis of - TATA STEEL LTD
A3: # | B3: Years | C3: ='Data Sheet'!B16 -> 42825 | D3: ='Data Sheet'!C16 -> 43190 | E3: ='Data Sheet'!D16 -> 43555 | F3: ='Data Sheet'!E16 -> 43921 | G3: ='Data Sheet'!F16 -> 44286 | H3: ='Data Sheet'!G16 -> 44651 | I3: ='Data Sheet'!H16 -> 45016 | J3: ='Data Sheet'!I16 -> 45382 | ... L3: ='Data Sheet'!K16 -> 46112 | M3: Trend | N3: Mean | O3: Median
B5: Sales Growth | D5: =IFERROR('HistoricalFS '!D6,0) -> 0.097504065 | E5: =IFERROR('HistoricalFS '!E6,0) -> 0.27927124 | F5: =IFERROR('HistoricalFS '!F6,0) -> -0.1132267 | G5: =IFERROR('HistoricalFS '!G6,0) -> 0.11916142 | H5: =IFERROR('HistoricalFS '!H6,0) -> 0.55906968 | I5: =IFERROR('HistoricalFS '!I6,0) -> -0.0024859898 | J5: =IFERROR('HistoricalFS '!J6,0) -> -0.058277186 | K5: =IFERROR('HistoricalFS '!K6,0) -> -0.046377073 | L5: =IFERROR('HistoricalFS '!L6,0) -> 0.062218696 | N5: =IFERROR(AVERAGE(D5:L5),0) -> 0.099650904 | O5: =IFERROR(MEDIAN(D5:L5),0) -> 0.062218696
B6: EBITDA Growth | D6: =IFERROR('HistoricalFS '!D17/'HistoricalFS '!C17-1,0) -> 0.6306903 | E6: =IFERROR('HistoricalFS '!E17/'HistoricalFS '!D17-1,0) -> 0.36788877 | F6: =IFERROR('HistoricalFS '!F17/'HistoricalFS '!E17-1,0) -> -0.40436152 | G6: =IFERROR('HistoricalFS '!G17/'HistoricalFS '!F17-1,0) -> 0.74678779 | H6: =IFERROR('HistoricalFS '!H17/'HistoricalFS '!G17-1,0) -> 1.081347 | I6: =IFERROR('HistoricalFS '!I17/'HistoricalFS '!H17-1,0) -> -0.49125555 | J6: =IFERROR('HistoricalFS '!J17/'HistoricalFS '!I17-1,0) -> -0.31121332 | K6: =IFERROR('HistoricalFS '!K17/'HistoricalFS '!J17-1,0) -> 0.13711529 | L6: =IFERROR('HistoricalFS '!L17/'HistoricalFS '!K17-1,0) -> 0.35788714 | N6: =IFERROR(AVERAGE(D6:L6),0) -> 0.23498732 | O6: =IFERROR(MEDIAN(D6:L6),0) -> 0.35788714
B7: EBIT Growth | D7: =IFERROR('HistoricalFS '!D26/'HistoricalFS '!C26-1,0) -> 3.267891 | E7: =IFERROR('HistoricalFS '!E26/'HistoricalFS '!D26-1,0) -> 0.39851906 | F7: =IFERROR('HistoricalFS '!F26/'HistoricalFS '!E26-1,0) -> -0.89600169 | G7: =IFERROR('HistoricalFS '!G26/'HistoricalFS '!F26-1,0) -> 8.1773694 | H7: =IFERROR('HistoricalFS '!H26/'HistoricalFS '!G26-1,0) -> 2.5807379 | I7: =IFERROR('HistoricalFS '!I26/'HistoricalFS '!H26-1,0) -> -0.65936393 | J7: =IFERROR('HistoricalFS '!J26/'HistoricalFS '!I26-1,0) -> -0.70850149 | K7: =IFERROR('HistoricalFS '!K26/'HistoricalFS '!J26-1,0) -> 0.55122998 | L7: =IFERROR('HistoricalFS '!L26/'HistoricalFS '!K26-1,0) -> 1.0210359 | N7: =IFERROR(AVERAGE(D7:L7),0) -> 1.5258796 | O7: =IFERROR(MEDIAN(D7:L7),0) -> 0.55122998
B8: Net Profit Growth | D8: =IFERROR('HistoricalFS '!D32/-'HistoricalFS '!C32-1,0) -> 17.037263 | E8: =IFERROR('HistoricalFS '!E32/'HistoricalFS '!D32-1,0) -> 0.11008091 | F8: =IFERROR('HistoricalFS '!F32/'HistoricalFS '!E32-1,0) -> -0.465997 | G8: =IFERROR('HistoricalFS '!G32/'HistoricalFS '!F32-1,0) -> 0.9742315 | H8: =IFERROR('HistoricalFS '!H32/'HistoricalFS '!G32-1,0) -> 4.0498476 | I8: =IFERROR('HistoricalFS '!I32/'HistoricalFS '!H32-1,0) -> -0.83914468 | J8: =IFERROR('HistoricalFS '!J32/'HistoricalFS '!I32-1,0) -> -0.83161121 | K8: =IFERROR('HistoricalFS '!K32/'HistoricalFS '!J32-1,0) -> 1.0966028 | L8: =IFERROR('HistoricalFS '!L32/'HistoricalFS '!K32-1,0) -> 3.4177826 | N8: =IFERROR(AVERAGE(D8:L8),0) -> 2.7276729 | O8: =IFERROR(MEDIAN(D8:L8),0) -> 0.9742315
B9: Dividend Growth | D9: =IFERROR('HistoricalFS '!D40/'HistoricalFS '!C40-1,0) -> 0.18021551 | E9: =IFERROR('HistoricalFS '!E40/'HistoricalFS '!D40-1,0) -> 0.29997536 | F9: =IFERROR('HistoricalFS '!F40/'HistoricalFS '!E40-1,0) -> -0.23076148 | G9: =IFERROR('HistoricalFS '!G40/'HistoricalFS '!F40-1,0) -> 1.4617851 | H9: =IFERROR('HistoricalFS '!H40/'HistoricalFS '!G40-1,0) -> 1.0381154 | I9: =IFERROR('HistoricalFS '!I40/'HistoricalFS '!H40-1,0) -> -0.29459179 | J9: =IFERROR('HistoricalFS '!J40/'HistoricalFS '!I40-1,0) -> 1.5657977e-05 | K9: =IFERROR('HistoricalFS '!K40/'HistoricalFS '!J40-1,0) -> 0 | L9: =IFERROR('HistoricalFS '!L40/'HistoricalFS '!K40-1,0) -> 0.1111121 | N9: =IFERROR(AVERAGE(D9:L9),0) -> 0.28509621 | O9: =IFERROR(MEDIAN(D9:L9),0) -> 0.1111121
B11: Gross Margin | C11: =IFERROR('HistoricalFS '!C12,0) -> 0.30919421 | D11: =IFERROR('HistoricalFS '!D12,0) -> 0.31269218 | E11: =IFERROR('HistoricalFS '!E12,0) -> 0.33030553 | F11: =IFERROR('HistoricalFS '!F12,0) -> 0.26646118 | G11: =IFERROR('HistoricalFS '!G12,0) -> 0.34188745 | H11: =IFERROR('HistoricalFS '!H12,0) -> 0.41135564 | I11: =IFERROR('HistoricalFS '!I12,0) -> 0.26719791 | J11: =IFERROR('HistoricalFS '!J12,0) -> 0.20079323 | ... L11: =IFERROR('HistoricalFS '!L12,0) -> 0.26149813 | N11: =IFERROR(AVERAGE(C11:L11),0) -> 0.29156574 | O11: =IFERROR(MEDIAN(C11:L11),0) -> 0.28819606
B12: EBITDA Margin | C12: =IFERROR('HistoricalFS '!C18,0) -> 0.11704094 | D12: =IFERROR('HistoricalFS '!D18,0) -> 0.17390143 | E12: =IFERROR('HistoricalFS '!E18,0) -> 0.18594792 | F12: =IFERROR('HistoricalFS '!F18,0) -> 0.12489972 | G12: =IFERROR('HistoricalFS '!G18,0) -> 0.19494355 | H12: =IFERROR('HistoricalFS '!H18,0) -> 0.26024826 | I12: =IFERROR('HistoricalFS '!I18,0) -> 0.13272983 | J12: =IFERROR('HistoricalFS '!J18,0) -> 0.09708009 | ... L12: =IFERROR('HistoricalFS '!L18,0) -> 0.1479816 | N12: =IFERROR(AVERAGE(C12:L12),0) -> 0.15505332 | O12: =IFERROR(MEDIAN(C12:L12),0) -> 0.14035571
B13: EBIT Margin | C13: =IFERROR(('HistoricalFS '!C17-'HistoricalFS '!C23)/'HistoricalFS '!C5,0) -> 0.066525277 | D13: =IFERROR(('HistoricalFS '!D17-'HistoricalFS '!D23)/'HistoricalFS '!D5,0) -> 0.12731528 | E13: =IFERROR(('HistoricalFS '!E17-'HistoricalFS '!E23)/'HistoricalFS '!E5,0) -> 0.13938308 | F13: =IFERROR(('HistoricalFS '!F17-'HistoricalFS '!F23)/'HistoricalFS '!F5,0) -> 0.064529725 | G13: =IFERROR(('HistoricalFS '!G17-'HistoricalFS '!G23)/'HistoricalFS '!G5,0) -> 0.13593413 | H13: =IFERROR(('HistoricalFS '!H17-'HistoricalFS '!H23)/'HistoricalFS '!H5,0) -> 0.22294337 | I13: =IFERROR(('HistoricalFS '!I17-'HistoricalFS '!I23)/'HistoricalFS '!I5,0) -> 0.094369041 | J13: =IFERROR(('HistoricalFS '!J17-'HistoricalFS '!J23)/'HistoricalFS '!J5,0) -> 0.053958711 | ... L13: =IFERROR(('HistoricalFS '!L17-'HistoricalFS '!L23)/'HistoricalFS '!L5,0) -> 0.096484603 | N13: =IFERROR(AVERAGE(C13:L13),0) -> 0.10695175 | O13: =IFERROR(MEDIAN(C13:L13),0) -> 0.095426822
B14: EBT Margin | C14: =IFERROR('HistoricalFS '!C27,0) -> 0.021358525 | D14: =IFERROR('HistoricalFS '!D27,0) -> 0.083057422 | E14: =IFERROR('HistoricalFS '!E27,0) -> 0.090799656 | F14: =IFERROR('HistoricalFS '!F27,0) -> 0.010648732 | G14: =IFERROR('HistoricalFS '!G27,0) -> 0.087321939 | H14: =IFERROR('HistoricalFS '!H27,0) -> 0.20055356 | I14: =IFERROR('HistoricalFS '!I27,0) -> 0.068486032 | J14: =IFERROR('HistoricalFS '!J27,0) -> 0.021198994 | ... L14: =IFERROR('HistoricalFS '!L27,0) -> 0.065610726 | N14: =IFERROR(AVERAGE(C14:L14),0) -> 0.068351936 | O14: =IFERROR(MEDIAN(C14:L14),0) -> 0.067048379
B15: Net Profit Margin | C15: =IFERROR('HistoricalFS '!C33,0) -> -0.0033790023 | D15: =IFERROR('HistoricalFS '!D33,0) -> 0.055533239 | E15: =IFERROR('HistoricalFS '!E33,0) -> 0.048188677 | F15: =IFERROR('HistoricalFS '!F33,0) -> 0.029018575 | G15: =IFERROR('HistoricalFS '!G33,0) -> 0.051189565 | H15: =IFERROR('HistoricalFS '!H33,0) -> 0.16580369 | I15: =IFERROR('HistoricalFS '!I33,0) -> 0.026736873 | J15: =IFERROR('HistoricalFS '!J33,0) -> 0.0047808015 | ... L15: =IFERROR('HistoricalFS '!L33,0) -> 0.043715011 | N15: =IFERROR(AVERAGE(C15:L15),0) -> 0.043209833 | O15: =IFERROR(MEDIAN(C15:L15),0) -> 0.036366793
B17: SalesExpenses%Sale | C17: =IFERROR('HistoricalFS '!C15,0) -> 0.19215326 | D17: =IFERROR('HistoricalFS '!D15,0) -> 0.13879074 | E17: =IFERROR('HistoricalFS '!E15,0) -> 0.14435762 | F17: =IFERROR('HistoricalFS '!F15,0) -> 0.14156147 | G17: =IFERROR('HistoricalFS '!G15,0) -> 0.1469439 | H17: =IFERROR('HistoricalFS '!H15,0) -> 0.15110738 | I17: =IFERROR('HistoricalFS '!I15,0) -> 0.13446808 | J17: =IFERROR('HistoricalFS '!J15,0) -> 0.10371313 | ... L17: =IFERROR('HistoricalFS '!L15,0) -> 0.11351653 | N17: =IFERROR(AVERAGE(C17:L17),0) -> 0.13651242 | O17: =IFERROR(MEDIAN(C17:L17),0) -> 0.1401761
B18: Depreciation%Sale | C18: =IFERROR('HistoricalFS '!C24,0) -> 0.050515666 | D18: =IFERROR('HistoricalFS '!D24,0) -> 0.046586153 | E18: =IFERROR('HistoricalFS '!E24,0) -> 0.046564832 | F18: =IFERROR('HistoricalFS '!F24,0) -> 0.060369992 | G18: =IFERROR('HistoricalFS '!G24,0) -> 0.059009416 | H18: =IFERROR('HistoricalFS '!H24,0) -> 0.03730489 | I18: =IFERROR('HistoricalFS '!I24,0) -> 0.038360784 | J18: =IFERROR('HistoricalFS '!J24,0) -> 0.043121379 | ... L18: =IFERROR('HistoricalFS '!L24,0) -> 0.051496998 | N18: =IFERROR(AVERAGE(C18:L18),0) -> 0.048101571 | O18: =IFERROR(MEDIAN(C18:L18),0) -> 0.047135875
B19: OperatingIncome%Sale | C19: =C13 -> 0.066525277 | D19: =D13 -> 0.12731528 | E19: =E13 -> 0.13938308 | F19: =F13 -> 0.064529725 | G19: =G13 -> 0.13593413 | H19: =H13 -> 0.22294337 | I19: =I13 -> 0.094369041 | J19: =J13 -> 0.053958711 | ... L19: =L13 -> 0.096484603 | N19: =IFERROR(AVERAGE(C19:L19),0) -> 0.10695175 | O19: =IFERROR(MEDIAN(C19:L19),0) -> 0.095426822
B21: Return on Capital Employed | C21: =IFERROR(('HistoricalFS '!C17-'HistoricalFS '!C23)/SUM('HistoricalFS '!C48:C50),0) -> 0.061826653 | D21: =IFERROR(('HistoricalFS '!D17-'HistoricalFS '!D23)/SUM('HistoricalFS '!D48:D50),0) -> 0.10254692 | E21: =IFERROR(('HistoricalFS '!E17-'HistoricalFS '!E23)/SUM('HistoricalFS '!E48:E50),0) -> 0.12946991 | F21: =IFERROR(('HistoricalFS '!F17-'HistoricalFS '!F23)/SUM('HistoricalFS '!F48:F50),0) -> 0.047509827 | G21: =IFERROR(('HistoricalFS '!G17-'HistoricalFS '!G23)/SUM('HistoricalFS '!G48:G50),0) -> 0.13070294 | H21: =IFERROR(('HistoricalFS '!H17-'HistoricalFS '!H23)/SUM('HistoricalFS '!H48:H50),0) -> 0.2862517 | I21: =IFERROR(('HistoricalFS '!I17-'HistoricalFS '!I23)/SUM('HistoricalFS '!I48:I50),0) -> 0.12217019 | J21: =IFERROR(('HistoricalFS '!J17-'HistoricalFS '!J23)/SUM('HistoricalFS '!J48:J50),0) -> 0.069036994 | ... L21: =IFERROR(('HistoricalFS '!L17-'HistoricalFS '!L23)/SUM('HistoricalFS '!L48:L50),0) -> 0.11512725 | N21: =IFERROR(AVERAGE(C21:L21),0) -> 0.11446395 | O21: =IFERROR(MEDIAN(C21:L21),0) -> 0.10883708
B22: Retained Earning % | C22: =IFERROR('HistoricalFS '!C43,0) -> 0 | D22: =IFERROR('HistoricalFS '!D43,0) -> 0.83271775 | E22: =IFERROR('HistoricalFS '!E43,0) -> 0.8041001 | F22: =IFERROR('HistoricalFS '!F43,0) -> 0.71780355 | G22: =IFERROR('HistoricalFS '!G43,0) -> 0.6262152 | H22: =IFERROR('HistoricalFS '!H43,0) -> 0.84602539 | I22: =IFERROR('HistoricalFS '!I43,0) -> 0.3242962 | J22: =IFERROR('HistoricalFS '!J43,0) -> 0 | ... L22: =IFERROR('HistoricalFS '!L43,0) -> 0.50830114 | N22: =IFERROR(AVERAGE(C22:L22),0) -> 0.46594593 | O22: =IFERROR(MEDIAN(C22:L22),0) -> 0.56725817
B23: Return On Equity Share | C23: =IFERROR('HistoricalFS '!C32/SUM('HistoricalFS '!C48:C49),0) -> -0.010033496 | D23: =IFERROR('HistoricalFS '!D32/SUM('HistoricalFS '!D48:D49),0) -> 0.11244209 | E23: =IFERROR('HistoricalFS '!E32/SUM('HistoricalFS '!E48:E49),0) -> 0.1102336 | F23: =IFERROR('HistoricalFS '!F32/SUM('HistoricalFS '!F48:F49),0) -> 0.055143844 | G23: =IFERROR('HistoricalFS '!G32/SUM('HistoricalFS '!G48:G49),0) -> 0.10789524 | H23: =IFERROR('HistoricalFS '!H32/SUM('HistoricalFS '!H48:H49),0) -> 0.35344508 | I23: =IFERROR('HistoricalFS '!I32/SUM('HistoricalFS '!I48:I49),0) -> 0.063119494 | J23: =IFERROR('HistoricalFS '!J32/SUM('HistoricalFS '!J48:J49),0) -> 0.011904286 | ... L23: =IFERROR('HistoricalFS '!L32/SUM('HistoricalFS '!L48:L49),0) -> 0.09932694 | N23: =IFERROR(AVERAGE(C23:L23),0) -> 0.092867276 | O23: =IFERROR(MEDIAN(C23:L23),0) -> 0.081223217
B24: Self Substained Growth rate | C24: =IFERROR(C22*C23,0) -> 0 | D24: =IFERROR(D22*D23,0) -> 0.093632527 | E24: =IFERROR(E22*E23,0) -> 0.088638853 | F24: =IFERROR(F22*F23,0) -> 0.039582447 | G24: =IFERROR(G22*G23,0) -> 0.06756564 | H24: =IFERROR(H22*H23,0) -> 0.29902351 | I24: =IFERROR(I22*I23,0) -> 0.020469412 | J24: =IFERROR(J22*J23,0) -> 0 | ... L24: =IFERROR(L22*L23,0) -> 0.050487997 | N24: =IFERROR(AVERAGE(C24:L24),0) -> 0.065940039 | O24: =IFERROR(MEDIAN(C24:L24),0) -> 0.045035222
B25: Interest Coverage Ratio | C25: =IFERROR(('HistoricalFS '!C17-'HistoricalFS '!C23)/'HistoricalFS '!C20,0) -> 1.4728816 | D25: =IFERROR(('HistoricalFS '!D17-'HistoricalFS '!D23)/'HistoricalFS '!D20,0) -> 2.8766706 | E25: =IFERROR(('HistoricalFS '!E17-'HistoricalFS '!E23)/'HistoricalFS '!E20,0) -> 2.868943 | F25: =IFERROR(('HistoricalFS '!F17-'HistoricalFS '!F23)/'HistoricalFS '!F20,0) -> 1.1976343 | G25: =IFERROR(('HistoricalFS '!G17-'HistoricalFS '!G23)/'HistoricalFS '!G20,0) -> 2.796297 | H25: =IFERROR(('HistoricalFS '!H17-'HistoricalFS '!H23)/'HistoricalFS '!H20,0) -> 9.9573578 | I25: =IFERROR(('HistoricalFS '!I17-'HistoricalFS '!I23)/'HistoricalFS '!I20,0) -> 3.6459841 | J25: =IFERROR(('HistoricalFS '!J17-'HistoricalFS '!J23)/'HistoricalFS '!J20,0) -> 1.6471055 | ... L25: =IFERROR(('HistoricalFS '!L17-'HistoricalFS '!L23)/'HistoricalFS '!L20,0) -> 3.125121 | N25: =IFERROR(AVERAGE(C25:L25),0) -> 3.1614588 | O25: =IFERROR(MEDIAN(C25:L25),0) -> 2.83262
B27: Debtor Turnover Ratio | C27: =IFERROR('HistoricalFS '!C5/'HistoricalFS '!C60,0) -> 9.6919966 | D27: =IFERROR('HistoricalFS '!D5/'HistoricalFS '!D60,0) -> 9.9270163 | E27: =IFERROR('HistoricalFS '!E5/'HistoricalFS '!E60,0) -> 13.349335 | F27: =IFERROR('HistoricalFS '!F5/'HistoricalFS '!F60,0) -> 17.732181 | G27: =IFERROR('HistoricalFS '!G5/'HistoricalFS '!G60,0) -> 16.402518 | H27: =IFERROR('HistoricalFS '!H5/'HistoricalFS '!H60,0) -> 19.92084 | I27: =IFERROR('HistoricalFS '!I5/'HistoricalFS '!I60,0) -> 29.471432 | J27: =IFERROR('HistoricalFS '!J5/'HistoricalFS '!J60,0) -> 36.588119 | ... L27: =IFERROR('HistoricalFS '!L5/'HistoricalFS '!L60,0) -> 47.212758 | N27: =IFERROR(AVERAGE(C27:L27),0) -> 24.184373 | O27: =IFERROR(MEDIAN(C27:L27),0) -> 18.82651
B28: Creditors Turnover Ratio | C28: =IFERROR('HistoricalFS '!C5/'HistoricalFS '!C51,0) -> 2.1757736 | D28: =IFERROR('HistoricalFS '!D5/'HistoricalFS '!D51,0) -> 2.2125526 | E28: =IFERROR('HistoricalFS '!E5/'HistoricalFS '!E51,0) -> 2.5014063 | F28: =IFERROR('HistoricalFS '!F5/'HistoricalFS '!F51,0) -> 2.359989 | G28: =IFERROR('HistoricalFS '!G5/'HistoricalFS '!G51,0) -> 1.9277973 | H28: =IFERROR('HistoricalFS '!H5/'HistoricalFS '!H51,0) -> 2.6397571 | I28: =IFERROR('HistoricalFS '!I5/'HistoricalFS '!I51,0) -> 2.4979585 | J28: =IFERROR('HistoricalFS '!J5/'HistoricalFS '!J51,0) -> 2.5408498 | ... L28: =IFERROR('HistoricalFS '!L5/'HistoricalFS '!L51,0) -> 2.2766565 | N28: =IFERROR(AVERAGE(C28:L28),0) -> 2.3574887 | O28: =IFERROR(MEDIAN(C28:L28),0) -> 2.4010674
B29: Inventory Turnover Ratio | C29: =IFERROR('HistoricalFS '!C5/'HistoricalFS '!C61,0) -> 4.527505 | D29: =IFERROR('HistoricalFS '!D5/'HistoricalFS '!D61,0) -> 4.3503193 | E29: =IFERROR('HistoricalFS '!E5/'HistoricalFS '!E61,0) -> 4.9806827 | F29: =IFERROR('HistoricalFS '!F5/'HistoricalFS '!F61,0) -> 4.5002385 | G29: =IFERROR('HistoricalFS '!G5/'HistoricalFS '!G61,0) -> 4.7023564 | H29: =IFERROR('HistoricalFS '!H5/'HistoricalFS '!H61,0) -> 4.996666 | I29: =IFERROR('HistoricalFS '!I5/'HistoricalFS '!I61,0) -> 4.4721348 | J29: =IFERROR('HistoricalFS '!J5/'HistoricalFS '!J61,0) -> 4.6619688 | ... L29: =IFERROR('HistoricalFS '!L5/'HistoricalFS '!L61,0) -> 4.9130957 | N29: =IFERROR(AVERAGE(C29:L29),0) -> 4.7006129 | O29: =IFERROR(MEDIAN(C29:L29),0) -> 4.6821626
B30: Fixed Assets Turnover Ratio | C30: =IFERROR('HistoricalFS '!C5/'HistoricalFS '!C54,0) -> 1.220559 | D30: =IFERROR('HistoricalFS '!D5/'HistoricalFS '!D54,0) -> 1.2824433 | E30: =IFERROR('HistoricalFS '!E5/'HistoricalFS '!E54,0) -> 1.2670088 | F30: =IFERROR('HistoricalFS '!F5/'HistoricalFS '!F54,0) -> 1.0391376 | G30: =IFERROR('HistoricalFS '!G5/'HistoricalFS '!G54,0) -> 1.1524743 | H30: =IFERROR('HistoricalFS '!H5/'HistoricalFS '!H54,0) -> 1.8303184 | I30: =IFERROR('HistoricalFS '!I5/'HistoricalFS '!I54,0) -> 1.6597345 | J30: =IFERROR('HistoricalFS '!J5/'HistoricalFS '!J54,0) -> 1.5399774 | ... L30: =IFERROR('HistoricalFS '!L5/'HistoricalFS '!L54,0) -> 1.2903249 | N30: =IFERROR(AVERAGE(C30:L30),0) -> 1.3730104 | O30: =IFERROR(MEDIAN(C30:L30),0) -> 1.2863841
B31: Capital Turnover Ratio | C31: =IFERROR('HistoricalFS '!C5/SUM('HistoricalFS '!C48:C49),0) -> 2.9693665 | D31: =IFERROR('HistoricalFS '!D5/SUM('HistoricalFS '!D48:D49),0) -> 2.0247711 | E31: =IFERROR('HistoricalFS '!E5/SUM('HistoricalFS '!E48:E49),0) -> 2.2875416 | F31: =IFERROR('HistoricalFS '!F5/SUM('HistoricalFS '!F48:F49),0) -> 1.9002947 | G31: =IFERROR('HistoricalFS '!G5/SUM('HistoricalFS '!G48:G49),0) -> 2.1077585 | H31: =IFERROR('HistoricalFS '!H5/SUM('HistoricalFS '!H48:H49),0) -> 2.1317082 | I31: =IFERROR('HistoricalFS '!I5/SUM('HistoricalFS '!I48:I49),0) -> 2.3607657 | J31: =IFERROR('HistoricalFS '!J5/SUM('HistoricalFS '!J48:J49),0) -> 2.4900189 | ... L31: =IFERROR('HistoricalFS '!L5/SUM('HistoricalFS '!L48:L49),0) -> 2.2721472 | N31: =IFERROR(AVERAGE(C31:L31),0) -> 2.294147 | O31: =IFERROR(MEDIAN(C31:L31),0) -> 2.2798444
B33: Debtors days | C33: =IFERROR(365/C27,0) -> 37.659939 | D33: =IFERROR(365/D27,0) -> 36.768349 | E33: =IFERROR(365/E27,0) -> 27.342187 | F33: =IFERROR(365/F27,0) -> 20.584045 | G33: =IFERROR(365/G27,0) -> 22.252681 | H33: =IFERROR(365/H27,0) -> 18.322521 | I33: =IFERROR(365/I27,0) -> 12.384875 | J33: =IFERROR(365/J27,0) -> 9.975916 | ... L33: =IFERROR(365/L27,0) -> 7.7309611 | N33: =IFERROR(AVERAGE(C33:L33),0) -> 20.180659 | O33: =IFERROR(MEDIAN(C33:L33),0) -> 19.453283
B34: Payable days | C34: =IFERROR(365/C28,0) -> 167.75643 | D34: =IFERROR(365/D28,0) -> 164.96783 | E34: =IFERROR(365/E28,0) -> 145.91792 | F34: =IFERROR(365/F28,0) -> 154.66174 | G34: =IFERROR(365/G28,0) -> 189.33526 | H34: =IFERROR(365/H28,0) -> 138.2703 | I34: =IFERROR(365/I28,0) -> 146.11932 | J34: =IFERROR(365/J28,0) -> 143.65273 | ... L34: =IFERROR(365/L28,0) -> 160.32282 | N34: =IFERROR(AVERAGE(C34:L34),0) -> 156.04631 | O34: =IFERROR(MEDIAN(C34:L34),0) -> 152.06023
B35: Inventory days | C35: =IFERROR(365/C29,0) -> 80.618353 | D35: =IFERROR(365/D29,0) -> 83.901887 | E35: =IFERROR(365/E29,0) -> 73.283126 | F35: =IFERROR(365/F29,0) -> 81.106812 | G35: =IFERROR(365/G29,0) -> 77.620658 | H35: =IFERROR(365/H29,0) -> 73.048709 | I35: =IFERROR(365/I29,0) -> 81.616503 | J35: =IFERROR(365/J29,0) -> 78.293102 | ... L35: =IFERROR(365/L29,0) -> 74.291246 | N35: =IFERROR(AVERAGE(C35:L35),0) -> 77.825253 | O35: =IFERROR(MEDIAN(C35:L35),0) -> 77.95688
B36: Cash Conversion Cycle (in days) | C36: =IFERROR(SUM(C33,C35)-C34,0) -> -49.478134 | D36: =IFERROR(SUM(D33,D35)-D34,0) -> -44.297593 | E36: =IFERROR(SUM(E33,E35)-E34,0) -> -45.292607 | F36: =IFERROR(SUM(F33,F35)-F34,0) -> -52.970883 | G36: =IFERROR(SUM(G33,G35)-G34,0) -> -89.461918 | H36: =IFERROR(SUM(H33,H35)-H34,0) -> -46.899069 | I36: =IFERROR(SUM(I33,I35)-I34,0) -> -52.117944 | J36: =IFERROR(SUM(J33,J35)-J34,0) -> -55.383708 | ... L36: =IFERROR(SUM(L33,L35)-L34,0) -> -78.300618 | N36: =IFERROR(AVERAGE(C36:L36),0) -> -58.040393 | O36: =IFERROR(MEDIAN(C36:L36),0) -> -52.544413
B38: CFO/Sales | C38: =IFERROR('HistoricalFS '!C103/'HistoricalFS '!C5,0) -> 0.096388387 | D38: =IFERROR('HistoricalFS '!D103/'HistoricalFS '!D5,0) -> 0.06509899 | E38: =IFERROR('HistoricalFS '!E103/'HistoricalFS '!E5,0) -> 0.16069076 | F38: =IFERROR('HistoricalFS '!F103/'HistoricalFS '!F5,0) -> 0.1442512 | G38: =IFERROR('HistoricalFS '!G103/'HistoricalFS '!G5,0) -> 0.28327848 | H38: =IFERROR('HistoricalFS '!H103/'HistoricalFS '!H5,0) -> 0.18191975 | I38: =IFERROR('HistoricalFS '!I103/'HistoricalFS '!I5,0) -> 0.08910146 | J38: =IFERROR('HistoricalFS '!J103/'HistoricalFS '!J5,0) -> 0.088583152 | ... L38: =IFERROR('HistoricalFS '!L103/'HistoricalFS '!L5,0) -> 0.1510488 | N38: =IFERROR(AVERAGE(C38:L38),0) -> 0.13662332 | O38: =IFERROR(MEDIAN(C38:L38),0) -> 0.12506171
B39: CFO/Total Assets | C39: =IFERROR('HistoricalFS '!C103/'HistoricalFS '!C65,0) -> 0.062769064 | D39: =IFERROR('HistoricalFS '!D103/'HistoricalFS '!D65,0) -> 0.038440532 | E39: =IFERROR('HistoricalFS '!E103/'HistoricalFS '!E65,0) -> 0.10884382 | F39: =IFERROR('HistoricalFS '!F103/'HistoricalFS '!F65,0) -> 0.080950396 | G39: =IFERROR('HistoricalFS '!G103/'HistoricalFS '!G65,0) -> 0.18173436 | H39: =IFERROR('HistoricalFS '!H103/'HistoricalFS '!H65,0) -> 0.15714442 | I39: =IFERROR('HistoricalFS '!I103/'HistoricalFS '!I65,0) -> 0.075975475 | J39: =IFERROR('HistoricalFS '!J103/'HistoricalFS '!J65,0) -> 0.075379628 | ... L39: =IFERROR('HistoricalFS '!L103/'HistoricalFS '!L65,0) -> 0.11825542 | N39: =IFERROR(AVERAGE(C39:L39),0) -> 0.098348969 | O39: =IFERROR(MEDIAN(C39:L39),0) -> 0.082473491
B40: CFO/Total Debt | C40: =IFERROR('HistoricalFS '!C103/'HistoricalFS '!C50,0) -> 0.13039121 | D40: =IFERROR('HistoricalFS '!D103/'HistoricalFS '!D50,0) -> 0.087071588 | E40: =IFERROR('HistoricalFS '!E103/'HistoricalFS '!E50,0) -> 0.25130827 | F40: =IFERROR('HistoricalFS '!F103/'HistoricalFS '!F50,0) -> 0.17337774 | G40: =IFERROR('HistoricalFS '!G103/'HistoricalFS '!G50,0) -> 0.50085846 | H40: =IFERROR('HistoricalFS '!H103/'HistoricalFS '!H50,0) -> 0.58735041 | I40: =IFERROR('HistoricalFS '!I103/'HistoricalFS '!I50,0) -> 0.25541643 | J40: =IFERROR('HistoricalFS '!J103/'HistoricalFS '!J50,0) -> 0.23312099 | ... L40: =IFERROR('HistoricalFS '!L103/'HistoricalFS '!L50,0) -> 0.37956075 | N40: =IFERROR(AVERAGE(C40:L40),0) -> 0.28425205 | O40: =IFERROR(MEDIAN(C40:L40),0) -> 0.24768643

Sheet Forecasting
B2: ='Data Sheet'!B1&" -"&'Data Sheet'!A17 &" Forecasting" -> TATA STEEL LTD -Sales Forecasting | G2: ='Data Sheet'!B1&" - "&'HistoricalFS '!B17 &" Forecasting" -> TATA STEEL LTD - EBITDA Forecasting | L2: ='Data Sheet'!B1&" - "&'HistoricalFS '!B37 &" Forecasting" -> TATA STEEL LTD - Earning Per Share Forecasting
B3: Growth Year | C3: Year | D3: Sales | E3: Sales Growth | G3: Growth Year | H3: Year | I3: Sales | J3: Sales Growth | L3: Growth Year | M3: Year | N3: Sales | O3: Sales Growth | Q3: SUMMARY OUTPUT
B4: 1 | C4: ='Data Sheet'!$B$16 -> 42825 | D4: {=TRANSPOSE('Data Sheet'!B17:K17)} -> 112299.42 | G4: 1 | H4: ='Data Sheet'!$B$16 -> 42825 | I4: {=TRANSPOSE('HistoricalFS '!C17:M17)} -> 13143.63 | L4: 1 | M4: ='Data Sheet'!$B$16 -> 42825 | N4: {=TRANSPOSE('HistoricalFS '!C37:M37)} -> -0.33681277
B5: =B4+1 -> 2 | C5: =C4+365 -> 43190 | D5: 123249.07 | E5: =D5/D4-1 -> 0.097504065 | G5: =G4+1 -> 2 | H5: =H4+365 -> 43190 | I5: 21433.19 | J5: =I5/I4-1 -> 0.6306903 | L5: =L4+1 -> 2 | M5: =M4+365 -> 43190 | N5: 6.0759357 | O5: =N5/N4-1 -> -19.039505 | Q5: Regression Statistics
B6: =B5+1 -> 3 | C6: =C5+365 -> 43555 | D6: 157668.99 | E6: =D6/D5-1 -> 0.27927124 | G6: =G5+1 -> 3 | H6: =H5+365 -> 43555 | I6: 29318.22 | J6: =I6/I5-1 -> 0.36788877 | L6: =L5+1 -> 3 | M6: =M5+365 -> 43555 | N6: 6.7447203 | O6: =N6/N5-1 -> 0.11007106 | Q6: Multiple R | R6: 0.87298507
B7: =B6+1 -> 4 | C7: =C6+365 -> 43920 | D7: 139816.65 | E7: =D7/D6-1 -> -0.1132267 | G7: =G6+1 -> 4 | H7: =H6+365 -> 43920 | I7: 17463.06 | J7: =I7/I6-1 -> -0.40436152 | L7: =L6+1 -> 4 | M7: =M6+365 -> 43920 | N7: 3.6017009 | O7: =N7/N6-1 -> -0.465997 | Q7: R Square | R7: 0.76210294
B8: =B7+1 -> 5 | C8: =C7+365 -> 44285 | D8: 156477.4 | E8: =D8/D7-1 -> 0.11916142 | G8: =G7+1 -> 5 | H8: =H7+365 -> 44285 | I8: 30504.26 | J8: =I8/I7-1 -> 0.74678779 | L8: =L7+1 -> 5 | M8: =M7+365 -> 44285 | N8: 6.6940305 | O8: =N8/N7-1 -> 0.85857482 | Q8: Adjusted R Square | R8: 0.7323658
B9: =B8+1 -> 6 | C9: =C8+365 -> 44650 | D9: 243959.17 | E9: =D9/D8-1 -> 0.55906968 | G9: =G8+1 -> 6 | H9: =H8+365 -> 44650 | I9: 63489.95 | J9: =I9/I8-1 -> 1.081347 | L9: =L8+1 -> 6 | M9: =M8+365 -> 44650 | N9: 33.119897 | O9: =N9/N8-1 -> 3.9476764 | Q9: Standard Error | R9: 27198.017
B10: =B9+1 -> 7 | C10: =C9+365 -> 45015 | D10: 243352.69 | E10: =D10/D9-1 -> -0.0024859898 | G10: =G9+1 -> 7 | H10: =H9+365 -> 45015 | I10: 32300.16 | J10: =I10/I9-1 -> -0.49125555 | L10: =L9+1 -> 7 | M10: =M9+365 -> 45015 | N10: 5.3238064 | O10: =N10/N9-1 -> -0.83925655 | Q10: Observations | R10: 10
B11: =B10+1 -> 8 | C11: =C10+365 -> 45380 | D11: 229170.78 | E11: =D11/D10-1 -> -0.058277186 | G11: =G10+1 -> 8 | H11: =H10+365 -> 45380 | I11: 22247.92 | J11: =I11/I10-1 -> -0.31121332 | L11: =L10+1 -> 8 | M11: =M10+365 -> 45380 | N11: 0.8776545 | O11: =N11/N10-1 -> -0.8351453
B12: =B11+1 -> 9 | C12: =C11+365 -> 45745 | D12: 218542.51 | E12: =D12/D11-1 -> -0.046377073 | G12: =G11+1 -> 9 | H12: =H11+365 -> 45745 | I12: 25298.45 | J12: =I12/I11-1 -> 0.13711529 | L12: =L11+1 -> 9 | M12: =M11+365 -> 45745 | N12: 1.8400929 | O12: =N12/N11-1 -> 1.0966028 | Q12: ANOVA
B13: =B12+1 -> 10 | C13: =C12+365 -> 46110 | D13: 232139.94 | E13: =D13/D12-1 -> 0.062218696 | G13: =G12+1 -> 10 | H13: =H12+365 -> 46110 | I13: 34352.44 | J13: =I13/I12-1 -> 0.35788714 | L13: =L12+1 -> 10 | M13: =M12+365 -> 46110 | N13: 8.1291305 | O13: =N13/N12-1 -> 3.4177826 | R13: df | S13: SS | T13: MS | U13: F | V13: Significance F
B14: =B13+1 -> 11 | C14: =C13+365 -> 46475 | D14: =FORECAST(B14,$D$4:$D$13,B$4:B$13) -> 269041.58 | E14: =D14/D13-1 -> 0.15896292 | G14: =G13+1 -> 11 | H14: =H13+365 -> 46475 | I14: =FORECAST(G14,$I$4:$I$13,$G$4:$G$13) -> 37624.515 | J14: =I14/I13-1 -> 0.095250138 | L14: =L13+1 -> 11 | M14: =M13+365 -> 46475 | N14: =FORECAST(L14,$N$4:$N$13,$L$4:$L$13) -> 8.8336637 | O14: =N14/N13-1 -> 0.086667725 | Q14: Regression | R14: 1 | S14: 1.8957847e+10 | T14: 1.8957847e+10 | U14: 25.62799 | V14: 0.00097413288
B15: =B14+1 -> 12 | C15: =C14+365 -> 46840 | D15: =FORECAST(B15,$D$4:$D$13,B$4:B$13) -> 284200.48 | E15: =D15/D14-1 -> 0.056344058 | G15: =G14+1 -> 12 | H15: =H14+365 -> 46840 | I15: =FORECAST(G15,$I$4:$I$13,$G$4:$G$13) -> 39200.767 | J15: =I15/I14-1 -> 0.041894284 | L15: =L14+1 -> 12 | M15: =M14+365 -> 46840 | N15: =FORECAST(L15,$N$4:$N$13,$L$4:$L$13) -> 9.1294179 | O15: =N15/N14-1 -> 0.033480356 | Q15: Residual | R15: 8 | S15: 5.9178569e+09 | T15: 7.3973211e+08
B16: =B15+1 -> 13 | C16: =C15+365 -> 47205 | D16: =FORECAST(B16,$D$4:$D$13,B$4:B$13) -> 299359.37 | E16: =D16/D15-1 -> 0.053338737 | G16: =G15+1 -> 13 | H16: =H15+365 -> 47205 | I16: =FORECAST(G16,$I$4:$I$13,$G$4:$G$13) -> 40777.019 | J16: =I16/I15-1 -> 0.040209727 | L16: =L15+1 -> 13 | M16: =M15+365 -> 47205 | N16: =FORECAST(L16,$N$4:$N$13,$L$4:$L$13) -> 9.4251721 | O16: =N16/N15-1 -> 0.032395735 | Q16: Total | R16: 9 | S16: 2.4875704e+10
B17: =B16+1 -> 14 | C17: =C16+365 -> 47570 | D17: =FORECAST(B17,$D$4:$D$13,B$4:B$13) -> 314518.27 | E17: =D17/D16-1 -> 0.050637782 | G17: =G16+1 -> 14 | H17: =H16+365 -> 47570 | I17: =FORECAST(G17,$I$4:$I$13,$G$4:$G$13) -> 42353.271 | J17: =I17/I16-1 -> 0.038655404 | L17: =L16+1 -> 14 | M17: =M16+365 -> 47570 | N17: =FORECAST(L17,$N$4:$N$13,$L$4:$L$13) -> 9.7209263 | O17: =N17/N16-1 -> 0.031379183
R18: Coefficients | S18: Standard Error | T18: t Stat | U18: P-value | V18: Lower 95% | W18: Upper 95% | X18: Lower 95.0% | Y18: Upper 95.0%
Q19: Intercept | R19: 102293.74 | S19: 18579.782 | T19: 5.505648 | U19: 0.00056993577 | V19: 59448.687 | W19: 145138.8 | X19: 59448.687 | Y19: 145138.8
Q20: Growth Year | R20: 15158.895 | S20: 2994.4031 | T20: 5.0624095 | U20: 0.00097413288 | V20: 8253.7887 | W20: 22064 | X20: 8253.7887 | Y20: 22064
S26: 204737

Sheet Cash Flow Data
C2: 42064 | D2: 42430 | E2: 42795 | F2: 43160 | G2: 43525 | H2: 43891 | I2: 44256 | J2: 44621 | K2: 44986 | L2: 45352 | M2: 45717 | N2: 46082
B3: Cash from Operating Activity - | C3: 11880 | D3: 11455 | E3: 10824 | F3: 8023 | G3: 25336 | H3: 20169 | I3: 44327 | J3: 44381 | K3: 21683 | L3: 20301 | M3: 23138 | N3: 35064
B4: Profit from operations | C4: 13955 | D4: 6824 | E4: 17581 | F4: 20187 | G4: 27840 | H4: 18078 | I4: 28540 | J4: 65900 | K4: 30908 | L4: 22237 | M4: 23929 | N4: 34219
B5: Receivables | C5: 1442 | D5: 0 | E5: 0 | F5: 0 | G5: 0 | H5: 0 | I5: 0 | J5: 0 | K5: 0 | L5: 0 | M5: 0 | N5: 0
B6: Inventory | C6: -485 | D6: 5618 | E6: -8243 | F6: -1595 | G6: -1069 | H6: 1562 | I6: 46 | J6: -16917 | K6: -4031 | L6: 5566 | M6: 4776 | N6: 1290
B7: Payables | C7: -605 | D7: 0 | E7: 0 | F7: 0 | G7: 0 | H7: 0 | I7: 0 | J7: 0 | K7: 0 | L7: 0 | M7: 0 | N7: 0
B8: Other WC items | C8: 0 | D8: 548 | E8: 3329 | F8: -7680 | G8: 3659 | H8: 2634 | I8: 16446 | J8: 7299 | K8: 325 | L8: -2182 | M8: -2569 | N8: 4152
B9: Working capital changes | C9: 351 | D9: 6166 | E9: -4914 | F9: -9276 | G9: 2591 | H9: 4196 | I9: 16491 | J9: -9618 | K9: -3706 | L9: 3384 | M9: 2207 | N9: 5442
B10: Direct taxes | C10: -2427 | D10: -1534 | E10: -1843 | F10: -2888 | G10: -5094 | H10: -2106 | I10: -704 | J10: -11902 | K10: -5519 | L10: -5320 | M10: -2998 | N10: -4597
B11: Cash from Investing Activity - | C11: -9021 | D11: -8794 | E11: -9490 | F11: -11730 | G11: -29176 | H11: -14012 | I11: -9437 | J11: -10905 | K11: -18179 | L11: -14253 | M11: -13611 | N11: -14397
B12: Fixed assets purchased | C12: -13492 | D12: -10163 | E12: -7716 | F12: -7478 | G12: -9091 | H12: -10398 | I12: -6979 | J12: -10522 | K12: -14142 | L12: -18207 | M12: -15671 | N12: -14559
B13: Fixed assets sold | C13: 1444 | D13: 231 | E13: 289 | F13: 179 | G13: 467 | H13: 386 | I13: 445 | J13: 569 | K13: 328 | L13: 475 | M13: 1264 | N13: 1401
B14: Investments purchased | C14: 1531 | D14: -3796 | E14: -861 | F14: -8641 | G14: -490 | H14: -828 | I14: -3631 | J14: -1153 | K14: -326 | L14: -4 | M14: -393 | N14: -553
... B30: Net Cash Flow | C30: 241 | D30: -2068 | E30: -1245 | F30: 2933 | G30: -4513 | H30: 4462 | I30: -2200 | J30: 10075 | K30: -3477 | L30: -5049 | M30: 2524 | N30: -720

Sheet WACC
B2: Weighted average cost of captial
B3: Tata Steel LTd - WACC Calculation
A5: # | B5: Peer comps
G6: Debt/ | H6: Debt/ | I6: Levered | J6: Unleverd | S6: Debt/ | T6: Debt/
B7: Name of the company | C7: Country | D7: Debt | E7: Equity | F7: Tax rate 1 | G7: Equity | H7: Capital | I7: Beta 2 | J7: Beta 3 | N7: Name of the company | O7: Country | P7: Debt | Q7: Equity | R7: Tax rate 1 | S7: Equity | T7: Capital
B9: JSW Steel | C9: India | D9: 99310 | E9: 324022.65 | F9: 0.3 | G9: =D9/E9 -> 0.30649092 | H9: =D9/(E9+D9) -> 0.23459093 | I9: 0.63 | J9: =I9/(1+(1-F9)*G9) -> 0.51871335 | N9: Tata Steel | O9: India | P9: 92381.68 | Q9: 235189.51 | R9: 0.3 | S9: =P9/Q9 -> 0.39279677 | T9: =P9/(Q9+P9) -> 0.28202016
B10: Steel Authority of India | C10: India | D10: 31927.71 | E10: 81288.74 | F10: 0.3 | G10: =D10/E10 -> 0.39276916 | H10: =D10/(E10+D10) -> 0.28200593 | I10: 1.05 | J10: =I10/(1+(1-F10)*G10) -> 0.82356919
B11: Jindal Steel & Power | C11: India | D11: 22609.55 | E11: 118840.26 | F11: 0.3 | G11: =D11/E11 -> 0.1902516 | H11: =D11/(E11+D11) -> 0.1598415 | I11: 0.67 | J11: =I11/(1+(1-F11)*G11) -> 0.59125849
B12: Jindal Stainless | C12: India | D12: 7460.33 | E12: 60829.8 | F12: 0.3 | G12: =D12/E12 -> 0.12264268 | H12: =D12/(E12+D12) -> 0.10924463 | I12: 0.55 | J12: =I12/(1+(1-F12)*G12) -> 0.50651569
E14: Average | F14: =AVERAGE(F9:F12) -> 0.3 | G14: =AVERAGE(G9:G12) -> 0.25303859 | H14: =AVERAGE(H9:H12) -> 0.19642075 | I14: =AVERAGE(I9:I12) -> 0.725 | J14: =AVERAGE(J9:J12) -> 0.61001418
E15: Median | F15: =MEDIAN(F9:F12) -> 0.3 | G15: =MEDIAN(G9:G12) -> 0.24837126 | H15: =MEDIAN(H9:H12) -> 0.19721622 | I15: =MEDIAN(I9:I12) -> 0.65 | J15: =MEDIAN(J9:J12) -> 0.55498592
B18: Cost of debt | G18: Cost of Equity
B20: Pre tax cost of debt | D20: 0.085 | G20: Risk free rate | J20: 0.0689
B21: Tax rate | D21: =R9 -> 0.3 | G21: Equity risk Premium | J21: =RM!G7-WACC!J20 -> 0.083711538
B22: Post tax Cost of debt | D22: =D20*(1-D21) -> 0.0595 | G22: Levered beta 4 | J22: =J31 -> 0.64994547
G23: Cost of Equity | J23: =J20+(J21*J22) -> 0.12330794
G26: Levered beta
B27: Capital Structure
G28: Comps median unlevered beta | J28: =J15 -> 0.55498592
D29: Current | E29: Target | G29: target debt/equity | J29: =E35 -> 0.24443233
B30: Total Debt | C30: =P9 -> 92381.68 | D30: =C30/$C$32 -> 0.28202016 | E30: =H14 -> 0.19642075 | G30: tax rate | J30: =R9 -> 0.3
B31: Total Equity | C31: =Q9 -> 235189.51 | D31: =C31/$C$32 -> 0.71797984 | E31: =E32-E30 -> 0.80357925 | G31: Levered beta | J31: =J28*(1+(1-J30)*J29) -> 0.64994547
B32: Total Capital | C32: =SUM(C30:C31) -> 327571.19 | D32: =C32/$C$32 -> 1 | E32: =D32 -> 1
G34: Weighted Average Cost of capital
B35: Targeted Debt/equity | D35: =D30/D31 -> 0.39279677 | E35: =E30/E31 -> 0.24443233
I36: Total Cost | J36: Total weight
G37: Debt | I37: =D22 -> 0.0595 | J37: =E30 -> 0.19642075
G38: Equity | I38: =J23 -> 0.12330794 | J38: =E31 -> 0.80357925
G39: Total | I39: =SUM(I37:I38) -> 0.18280794 | J39: =SUM(J37:J38) -> 1
G41: WACC | I41: =(I37*J37)+(I38*J38) -> 0.11077473

Sheet Beta
A2: Jindal Steel | F2: Nifty
A5: Month | B5: Closing price | C5: Return | F5: Closing price | G5: Return
A6: 42736 | B6: 78.93 | F6: 8561.3 | J6: Beta | K6: =SLOPE(C62:C121,G62:G121) -> 1.2320132
A7: 42767 | B7: 123.55 | C7: =B7/B6-1 -> 0.56531104 | F7: 8879.6 | G7: =(F7/F6)-1 -> 0.037178933
A8: 42795 | B8: 119.36 | C8: =B8/B7-1 -> -0.033913395 | F8: 9173.7 | G8: =(F8/F7)-1 -> 0.033120861
A9: 42826 | B9: 112.31 | C9: =B9/B8-1 -> -0.059065013 | F9: 9304 | G9: =(F9/F8)-1 -> 0.014203647 | J9: Beta Drafiting
A10: 42856 | B10: 119.71 | C10: =B10/B9-1 -> 0.065889057 | F10: 9621.2 | G10: =(F10/F9)-1 -> 0.034092863
A11: 42887 | B11: 121.38 | C11: =B11/B10-1 -> 0.01395038 | F11: 9520.9 | G11: =(F11/F10)-1 -> -0.010424895 | J11: Levered Raw beta | K11: =K6 -> 1.2320132
A12: 42917 | B12: 150.82 | C12: =B12/B11-1 -> 0.24254408 | F12: 10077 | G12: =(F12/F11)-1 -> 0.058408344 | J12: Raw beta weight | K12: 0.75
A13: 42948 | B13: 135.09 | C13: =B13/B12-1 -> -0.10429651 | F13: 9917.9 | G13: =(F13/F12)-1 -> -0.015788429
A14: 42979 | B14: 133.27 | C14: =B14/B13-1 -> -0.0134725 | F14: 9788.6 | G14: =(F14/F13)-1 -> -0.013037034 | J14: market beta | K14: 1
A15: 43009 | B15: 161.17 | C15: =B15/B14-1 -> 0.20934944 | F15: 10335 | G15: =(F15/F14)-1 -> 0.055820036 | J15: Market Beta weight | K15: 0.25
A16: 43040 | B16: 169.4 | C16: =B16/B15-1 -> 0.051064094 | F16: 10226 | G16: =(F16/F15)-1 -> -0.010546686
A17: 43070 | B17: 202.14 | C17: =B17/B16-1 -> 0.19327037 | F17: 10530 | G17: =(F17/F16)-1 -> 0.029728144 | J17: Adjusted Beta | K17: =(K11*K12)+(K14*K15) -> 1.1740099
A18: 43101 | B18: 261.75 | C18: =B18/B17-1 -> 0.29489463 | F18: 11027.7 | G18: =(F18/F17)-1 -> 0.047264957
A19: 43132 | B19: 250.12 | C19: =B19/B18-1 -> -0.04443171 | F19: 10492.85 | G19: =(F19/F18)-1 -> -0.048500594
A20: 43160 | B20: 214.96 | C20: =B20/B19-1 -> -0.14057253 | F20: 10113.7 | G20: =(F20/F19)-1 -> -0.036134129
A21: 43191 | B21: 248 | C21: =B21/B20-1 -> 0.15370301 | F21: 10739.35 | G21: =(F21/F20)-1 -> 0.061861633
A22: 43221 | B22: 225.76 | C22: =B22/B21-1 -> -0.089677419 | F22: 10736.15 | G22: =(F22/F21)-1 -> -0.00029796962
A23: 43252 | B23: 219.5 | C23: =B23/B22-1 -> -0.027728561 | F23: 10714.3 | G23: =(F23/F22)-1 -> -0.0020351802
A24: 43282 | B24: 201.55 | C24: =B24/B23-1 -> -0.081776765 | F24: 11356.5 | G24: =(F24/F23)-1 -> 0.059938587
A25: 43313 | B25: 216.88 | C25: =B25/B24-1 -> 0.076060531 | F25: 11680.5 | G25: =(F25/F24)-1 -> 0.028529917
A26: 43344 | B26: 193.07 | C26: =B26/B25-1 -> -0.10978421 | F26: 10930.45 | G26: =(F26/F25)-1 -> -0.064213861
A27: 43374 | B27: 167.88 | C27: =B27/B26-1 -> -0.13047081 | F27: 10386.6 | G27: =(F27/F26)-1 -> -0.0497555
A28: 43405 | B28: 152.15 | C28: =B28/B27-1 -> -0.093697879 | F28: 10876.75 | G28: =(F28/F27)-1 -> 0.047190611
A29: 43435 | B29: 162.45 | C29: =B29/B28-1 -> 0.067696352 | F29: 10862.55 | G29: =(F29/F28)-1 -> -0.001305537
... A121: 46235 | B121: 1307 | C121: =B121/B120-1 -> 0.029133858 | F121: 24080 | G121: =(F121/F120)-1 -> -0.012450992
A122: sep | B122: 1302 | C122: =B122/B121-1 -> -0.0038255547 | F122: 23838 | G122: =(F122/F121)-1 -> -0.010049834

Sheet RM
A2: Return on Market
B3: Year | C3: Annual
B4: 2000 | C4: -0.1465 | F4: Average Return | G4: =AVERAGE(C4:C29) -> 0.15261154
B5: 2001 | C5: -0.1394 | F5: Dividend Yield | G5: 2.92% 1
B6: 2002 | C6: 0.0325
B7: 2003 | C7: 0.719 | F7: Total Return on Market | G7: =SUM(G4:G5) -> 0.15261154
B8: 2004 | C8: 0.1068
B9: 2005 | C9: 0.3634
B10: 2006 | C10: 0.3983
B11: 2007 | C11: 0.5477
B12: 2008 | C12: -0.5179
B13: 2009 | C13: 0.7576
B14: 2010 | C14: 0.1795
B15: 2011 | C15: -0.2462
B16: 2012 | C16: 0.277
B17: 2013 | C17: 0.0676
B18: 2014 | C18: 0.3139
B19: 2015 | C19: -0.0406
... B29: 2025 | C29: 0.1051

Sheet Common Size Statement
B2: ="Common Size Income Statement" &" "&"-"&'Data Sheet'!B1 -> Common Size Income Statement -TATA STEEL LTD
B4: Particular | C4: ='Data Sheet'!B16 -> 42825 | D4: ='Data Sheet'!C16 -> 43190 | E4: ='Data Sheet'!D16 -> 43555 | F4: ='Data Sheet'!E16 -> 43921 | G4: ='Data Sheet'!F16 -> 44286 | H4: ='Data Sheet'!G16 -> 44651 | I4: ='Data Sheet'!H16 -> 45016 | J4: ='Data Sheet'!I16 -> 45382 | ... L4: ='Data Sheet'!K16 -> 46112
B6: ='Data Sheet'!A17 -> Sales | C6: ='Data Sheet'!B17/'Data Sheet'!B$17 -> 1 | D6: ='Data Sheet'!C17/'Data Sheet'!C$17 -> 1 | E6: ='Data Sheet'!D17/'Data Sheet'!D$17 -> 1 | F6: ='Data Sheet'!E17/'Data Sheet'!E$17 -> 1 | G6: ='Data Sheet'!F17/'Data Sheet'!F$17 -> 1 | H6: ='Data Sheet'!G17/'Data Sheet'!G$17 -> 1 | I6: ='Data Sheet'!H17/'Data Sheet'!H$17 -> 1 | J6: ='Data Sheet'!I17/'Data Sheet'!I$17 -> 1 | ... L6: ='Data Sheet'!K17/'Data Sheet'!K$17 -> 1
B7: ='Data Sheet'!A18 -> Raw Material Cost | C7: ='Data Sheet'!B18/'Data Sheet'!B$17 -> 0.3904119 | D7: ='Data Sheet'!C18/'Data Sheet'!C$17 -> 0.37433962 | E7: ='Data Sheet'!D18/'Data Sheet'!D$17 -> 0.38610668 | F7: ='Data Sheet'!E18/'Data Sheet'!E$17 -> 0.41511501 | G7: ='Data Sheet'!F18/'Data Sheet'!F$17 -> 0.3521327 | H7: ='Data Sheet'!G18/'Data Sheet'!G$17 -> 0.37332727 | I7: ='Data Sheet'!H18/'Data Sheet'!H$17 -> 0.47912842 | J7: ='Data Sheet'!I18/'Data Sheet'!I$17 -> 0.42547479 | ... L7: ='Data Sheet'!K18/'Data Sheet'!K$17 -> 0.39901824
B8: ='Data Sheet'!A19 -> Change in Inventory | C8: ='Data Sheet'!B19/'Data Sheet'!B$17 -> 0.040410983 | D8: ='Data Sheet'!C19/'Data Sheet'!C$17 -> -0.00080576673 | E8: ='Data Sheet'!D19/'Data Sheet'!D$17 -> 0.00061337363 | F8: ='Data Sheet'!E19/'Data Sheet'!E$17 -> 0.0040427231 | G8: ='Data Sheet'!F19/'Data Sheet'!F$17 -> -0.0096932209 | H8: ='Data Sheet'!G19/'Data Sheet'!G$17 -> 0.031144023 | I8: ='Data Sheet'!H19/'Data Sheet'!H$17 -> 0.01380256 | J8: ='Data Sheet'!I19/'Data Sheet'!I$17 -> -0.019240455 | ... L8: ='Data Sheet'!K19/'Data Sheet'!K$17 -> -0.004263032
